Workbook

Sheet Dashboard
B2: CONNPLEX SIGNATURE — AHMEDABAD
B5: LUXURY RECLINER MULTIPLEX • INVESTOR ROI DASHBOARD • FOFO FRANCHISE MODEL
B7: TOTAL INVESTMENT | D7: YEAR-1 NET PROFIT | F7: RETURN ON INVESTMENT | H7: PAYBACK PERIOD | J7: BLENDED OCCUPANCY
B9: =Investment!E18 -> 38257000 | D9: ='ROI Calculation'!D34 -> 11741829 | F9: ='ROI Calculation'!D40 -> 0.30691976 | H9: ='ROI Calculation'!D41 -> 3.2581806 | J9: ='ROI Calculation'!G10 -> 0.34
B11: 3 Screens · 200 Luxury Recliner Seats · ConnPlex Franchise (Founded Gujarat, 2019) · Ahmedabad, Gujarat
B13: MONTHLY REVENUE BY STREAM | G13: REVENUE MIX | J13: 3-YEAR NET PROFIT TRAJECTORY
B14: Stream | C14: ₹ / Month | G14: Stream | H14: Share | J14: Year | K14: Net Profit (₹)
B15: Tickets | C15: ='ROI Calculation'!J15 -> 952512 | G15: Tickets | H15: =C15/SUM($C$15:$C$17) -> 0.43135826 | J15: Year 1 | K15: ='ROI Calculation'!D34 -> 11741829
B16: Food & Beverage | C16: ='ROI Calculation'!E25 -> 1031657.1 | G16: Food & Beverage | H16: =C16/SUM($C$15:$C$17) -> 0.46720024 | J16: Year 2 | K16: ='ROI Calculation'!D36 -> 12681175
B17: Advertisement | C17: ='ROI Calculation'!K22 -> 224000 | G17: Advertisement | H17: =C17/SUM($C$15:$C$17) -> 0.1014415 | J17: Year 3 | K17: ='ROI Calculation'!D37 -> 13695669
B36: INVESTMENT ALLOCATION | G36: WHY AHMEDABAD, WHY NOW — MARKET SIGNALS
B37: Component | C37: ₹ | G37: • ConnPlex is a Gujarat-founded (2019) cinema franchise, already running 33+ screens across the state with 250 more planned — the brand states Gujarat can support 300 additional screens. Source: bilkulonline.com, Dec 2024. • Ahmedabad had 130 movie theatres as of Oct 2025, up 10% since 2023 — including PVR INOX's 9-screen flagship IMAX/LUXE launch at Phoenix Palladium. Source: rentechdigital.com; newsonprojects.com. • India has ~9,500 screens for 1.43bn people (1 per ~147,000) vs the US (1 per 8,000) — the industry sees room for 25,000+ more Indian screens. Source: ConnPlex franchise disclosure, franchiseavs.com. • Gujarati-language box office alone grew from ₹46 cr (2015) to ₹104+ cr (Oct 2025) — 100%+ growth in a decade. Source: articles.uvnetware.com, Jan 2026. • National multiplex ATP: ₹259-262; F&B spend-per-head hit a record ₹148 in Q1 FY26 — both trending up. Source: PVR INOX investor disclosures / ICICI Direct, 2025-26.
B38: Seating + Franchise Fee | C38: =Investment!E12 -> 24550000
B39: Foyer / Lobby Fit-Out | C39: =Investment!E13 -> 6600000
B40: GST @ 18% | C40: =Investment!E15 -> 5607000
B41: Pre-Opening & Working Capital | C41: =Investment!E16 -> 1500000
B60: HOW MOVIES EARN — RECENT INDIAN BOX-OFFICE BENCHMARKS
B61: FILM (YEAR) | D61: OPENING DAY | F61: OPENING WKND | H61: WORLDWIDE GROSS | J61: TAKEAWAY
B62: Dhurandhar (2025) | D62: ₹90 cr (record) | F62: ₹443 cr (record) | H62: ₹1,349.7 cr | J62: A single well-marketed tentpole can fill every recliner in the country for weeks - proof of the demand a great slate creates.
B63: Chhaava (2025) | D63: — | F63: — | H63: ₹797-808 cr | J63: Mid-budget period drama outperforming expectations shows genre diversity, not just star power, drives footfalls.
B64: Saiyaara (2025) | D64: — | F64: — | H64: ₹579 cr | J64: A modestly-budgeted romance became a sleeper hit - premium recliner formats let smaller films still deliver strong per-screen yields.
B65: Kantara: Ch.1 (2025) | D65: — | F65: — | H65: ₹852 cr | J65: Regional-language content is now routinely crossing ₹800cr+ nationally, widening the content pipeline for every screen.
B67: Sources: Bollywood Hungama Box Office Report 2025-26; Wikipedia – List of Hindi films of 2025; Hollywood Reporter India, Feb 2026.
B69: This dashboard is 100% formula-linked to the ROI Calculation and Investment tabs. Every chart and KPI updates automatically when an assumption changes. All external figures are sourced - see the Assumptions & Sources tab.

Sheet ROI Calculation
B1: CONNPLEX SIGNATURE • LUXURY RECLINER MULTIPLEX
B3: 3-Screen FOFO Franchise Model — Ahmedabad, Gujarat | Investor ROI Projection, FY 2026-27
B4: Champagne-gold cells = editable assumption · White cells = auto-calculated formula · Navy/gold cells = key result. See 'Assumptions & Sources' tab for every citation.
B6: 1. TICKET REVENUE
B7: PARTICULAR | C7: SEATS (TOTAL) | D7: SHOWS / DAY | E7: OPERATING DAYS / MO. | F7: SEAT-SHOWS AVAILABLE | G7: OCCUPANCY % | H7: TICKETS SOLD | I7: ATP (₹) | J7: MONTHLY REVENUE (₹) | K7: ANNUAL REVENUE (₹)
B8: MON – THURSDAY | C8: 200 | D8: 5 | E8: 18 | F8: =C8*D8*E8 -> 18000 | G8: 0.2 | H8: =F8*G8 -> 3600 | I8: 220 | J8: =I8*H8 -> 792000 | K8: =J8*12 -> 9504000
B9: FRI – SUNDAY | C9: =C8 -> 200 | D9: 5 | E9: 12 | F9: =C9*D9*E9 -> 12000 | G9: 0.55 | H9: =F9*G9 -> 6600 | I9: 320 | J9: =I9*H9 -> 2112000 | K9: =J9*12 -> 25344000
B10: GROSS TICKET COLLECTION | F10: =SUM(F8:F9) -> 30000 | G10: =(H8+H9)/F10 -> 0.34 | H10: =SUM(H8:H9) -> 10200 | J10: =SUM(J8:J9) -> 2904000 | K10: =SUM(K8:K9) -> 34848000
B11: Less: GST on Tickets @ 18% | I11: 0.18 | J11: =J10*I11 -> 522720 | K11: =J11*12 -> 6272640
B12: Less: Distributor / Producer Share | G12: % of Net Box Office → | I12: 0.5 | J12: =(J10-J11)*I12 -> 1190640 | K12: =J12*12 -> 14287680
B13: TOTAL DEDUCTIONS (GST + Distributor) | J13: =SUM(J11:J12) -> 1713360 | K13: =SUM(K11:K12) -> 20560320
B14: EXHIBITOR'S NET TICKET SHARE | H14: (Gross Collection − Deductions) | J14: =J10-J13 -> 1190640 | K14: =K10-K13 -> 14287680
B15: FRANCHISEE NET TICKET INCOME | H15: after Brand Royalty | I15: 0.8 | J15: =J14*I15 -> 952512 | K15: =J15*12 -> 11430144
B17: 2. FOOD & BEVERAGE REVENUE | H17: 3. ADVERTISEMENT REVENUE
B18: PARTICULAR | C18: QTY | D18: RATE (₹) | E18: AMOUNT (₹) | H18: PARTICULAR | I18: QTY | J18: RATE (₹) | K18: AMOUNT (₹)
B19: Banquet / Private Screening | C19: 0 | D19: =C8*99 -> 19800 | E19: =D19*C19 -> 0 | H19: On-Screen / Lobby Ads | I19: 40 | J19: 10000 | K19: =J19*I19 -> 400000
B20: Food & Beverage (Concessions) | C20: =H10 -> 10200 | D20: 180 | E20: =D20*C20 -> 1836000 | H20: Less: Agency / Sales Commission | J20: 0.3 | K20: =K19*J20 -> 120000
B21: GROSS F&B INCOME | E21: =SUM(E19:E20) -> 1836000 | H21: GROSS AD REVENUE | K21: =K19-K20 -> 280000
B22: Less: GST @ 5% (F&B sold stand-alone) | C22: 0.05 | E22: =E21*C22/(1+C22) -> 87428.571 | H22: FRANCHISEE NET AD INCOME | J22: 0.8 | K22: =K21*J22 -> 224000
B23: Less: F&B Cost (COGS) @ 25% | C23: 0.25 | E23: =E21*C23 -> 459000
B24: NET F&B REVENUE | E24: =E21-E22-E23 -> 1289571.4
B25: FRANCHISEE NET F&B INCOME | D25: 0.8 | E25: =E24*D25 -> 1031657.1
B27: 6. SUMMARY OF RETURNS | H27: 4. MONTHLY OPERATING EXPENSES (FRANCHISEE)
B28: Screens | D28: 3 | H28: PARTICULAR | I28: MONTHLY (₹) | J28: ANNUAL (₹)
B29: Total Seats | D29: =C8 -> 200 | H29: Property Rent | I29: 500000 | J29: =I29*12 -> 6000000
B30: Blended Occupancy | D30: =G10 -> 0.34 | H30: CAM Charges | I30: 80000 | J30: =I30*12 -> 960000
B31: Average Ticket Price (Blended) | D31: =J10/H10 -> 284.70588 | H31: Internet & Digital Systems | I31: 15000 | J31: =I31*12 -> 180000
H32: Electricity (Power & HVAC) | I32: 180000 | J32: =I32*12 -> 2160000
B33: Net Profit / Month (Year 1) | D33: =I49 -> 978485.76 | H33: Equipment AMC | I33: 40000 | J33: =I33*12 -> 480000
B34: Net Profit / Year (Year 1) | D34: =J49 -> 11741829 | H34: Insurance | I34: 15000 | J34: =I34*12 -> 180000
B35: Assumed Annual Growth (Yr 2+) | D35: 0.08 | H35: Admin / Miscellaneous | I35: 50000 | J35: =I35*12 -> 600000
B36: Net Profit / Year 2 | D36: =D34*(1+D35) -> 12681175 | H36: Projection Operators (2) | I36: 50000 | J36: =I36*12 -> 600000
B37: Net Profit / Year 3 | D37: =D36*(1+D35) -> 13695669 | H37: F&B + Ticketing Staff | I37: 150000 | J37: =I37*12 -> 1800000
H38: Housekeeping Staff | I38: 60000 | J38: =I38*12 -> 720000
B39: TOTAL INVESTMENT REQUIRED | D39: =Investment!E18 -> 38257000 | H39: Security Staff | I39: 50000 | J39: =I39*12 -> 600000
B40: RETURN ON INVESTMENT (Yr 1, p.a.) | D40: =D34/D39 -> 0.30691976 | H40: Marketing & Promotion (2%) | I40: =(J15+E25)*0.02 -> 39683.383 | J40: =I40*12 -> 476200.59
B41: PAYBACK PERIOD | D41: =D39/D34 -> 3.2581806 | H41: TOTAL OPERATING EXPENSES | I41: =SUM(I29:I40) -> 1229683.4 | J41: =SUM(J29:J40) -> 14756201
H43: 5. FRANCHISEE PROFIT SUMMARY
H44: PARTICULAR | I44: MONTHLY (₹) | J44: ANNUAL (₹)
H45: Ticket Income | I45: =J15 -> 952512 | J45: =I45*12 -> 11430144
...

Sheet Investment
B1: CONNPLEX SIGNATURE • INVESTMENT CALCULATION
B3: FOFO (Franchise-Owned, Franchise-Operated) Model — 3 Screens
B4: Champagne-gold = editable input · White = formula · Navy/gold = key total
B6: 1. SEATING & AUDITORIUM INVESTMENT | G6: PRICE LIST REFERENCE
B7: PRODUCT DETAILS | C7: PRICE / SEAT (₹) | D7: NUMBER OF SEATS | E7: TOTAL (₹) | G7: Seat / Item | H7: Price (₹)
B8: Sofa Slider | C8: 85000 | D8: 80 | E8: =C8*D8 -> 6800000 | G8: Sofa Slider | H8: 85000
B9: Recliners | C9: 150000 | D9: 50 | E9: =C9*D9 -> 7500000 | G9: Fixed Couple Lounger | H9: 125000
B10: Duo Loungers (Couple Seating) | C10: 125000 | D10: 70 | E10: =C10*D10 -> 8750000 | G10: Automatic Recliner Sofa | H10: 150000
B11: Franchise Fee (per screen) | C11: 500000 | D11: 3 | E11: =C11*D11 -> 1500000 | G11: Franchise Fee / Screen | H11: 500000
B12: SUBTOTAL: Seating + Franchise Fee | E12: =SUM(E8:E11) -> 24550000
B13: Foyer / Lobby Fit-Out (Sq.Ft) | C13: 3000 | D13: 2200 | E13: =C13*D13 -> 6600000 | G13: ConnPlex Signature specification (per franchise disclosure): • Area required: 6,000-9,000 sq.ft • Screens: 3 • Seating: Sofa Sliders, Duo Loungers, Recliners • Capacity: up to ~175-260 seats • Franchisor-claimed occupancy: 60%+ • Franchisor-claimed payback: 3-4 years Source: franchiseavs.com/connplex-smart-theatres-franchise-in-india/
B14: TOTAL AUDITORIUM + FOYER INVESTMENT | E14: =E12+E13 -> 31150000
B15: GST @ 18% (on equipment & fit-out) | C15: 0.18 | E15: =E14*C15 -> 5607000
B16: Pre-Opening Marketing & Working Capital Reserve | E16: 1500000
B18: TOTAL INVESTMENT OF THE THEATRE | E18: =E14+E15+E16 -> 38257000
B20: * GST is extra / applicable as per prevailing government norms.
B21: * Minimum ceiling height: 12 ft (per ConnPlex build specification).
B22: * Outer-area / facade beautification charges are extra, and civil construction is not included in the ConnPlex franchise package.
B23: * ConnPlex's own disclosed estimate: Rs.2-4 crore total investment depending on format & city (Source: franchiseavs.com/connplex-smart-theatres-franchise-in-india).

Sheet Assumptions & Sources
B1: ASSUMPTIONS & SOURCES
B3: Every hard-coded figure in this workbook, why it was chosen, and where it comes from.
B5: ASSUMPTION | C5: VALUE USED | D5: RATIONALE | E5: SOURCE
B6: TICKET REVENUE
B7: Total seats (3 screens) | C7: 200 | D7: ConnPlex Signature format case studies show 3-screen layouts of 150-260 seats. | E7: franchiseavs.com/connplex-smart-theatres-franchise-in-india/
B8: Weekday occupancy | C8: 20% | D8: PVR INOX's national all-screen average occupancy is ~22-24%; modelled slightly below chain average for a new single-location weekday. | E8: ICICI Direct / Sharekhan PVR INOX research notes, Aug 2025
B9: Weekend occupancy | C9: 55% | D9: Prudent haircut vs. ConnPlex's own '60%+ industry-leading occupancy' franchise claim. | E9: franchiseavs.com/connplex-smart-theatres-franchise-in-india/
B10: Weekday ATP | C10: ₹220 | D10: Below the national blended ATP; weekend pricing carries the premium instead. | E10: Business Standard, Oct 2025 (PVR INOX Q2 FY26 ATP ₹262)
B11: Weekend / holiday ATP | C11: ₹320 | D11: Moderate premium vs. national ATP; PVR has stated select premium/recliner screens price ₹600-700. | E11: aparnadecors.com, Dec 2025, citing PVR INOX MD Ajay Bijli
B12: GST on tickets (>₹100) | C12: 18% | D12: Unchanged under the GST 2.0 reform effective 22-Sep-2025 (only the ≤₹100 slab was cut, from 12% to 5%). | E12: The Hans India, Sep 2025; GST Council 56th meeting
B13: Distributor / producer share | C13: 50% | D13: Industry week-1 nett split; exhibitor share actually rises to 57.5/62.5/70% in later weeks - this model conservatively holds the highest distributor rate throughout. | E13: Koimoi.com trade analysis; IndiaForums Bollywood trade desk
B14: Franchisee ticket/F&B/ad share | C14: 80% (20% royalty) | D14: Assumed ConnPlex brand royalty, within the typical 10-20% Indian franchise royalty band. Edit to match your signed agreement. | E14: Industry-typical franchise royalty range (assumption, not brand-specific disclosure)
B15: FOOD & BEVERAGE
B16: F&B Spend-Per-Head (SPH) | C16: ₹180 | D16: Premium-format uplift vs. PVR INOX's record national SPH of ₹148 (Q1 FY26) / ₹134 (FY25 avg). | E16: ICICI Direct, Aug 2025; Digital Cinema Report, Aug 2025
B17: F&B GST | C17: 5% | D17: F&B sold stand-alone (not bundled with the ticket) is taxed as a restaurant service at 5% under GST 2.0 - bundled combos revert to the 18% ticket rate. | E17: Business Standard; GST Council 50th & 56th meetings
B18: F&B cost ratio (COGS) | C18: 25% | D18: Cinema concessions typically carry 70-75% gross margin industry-wide. | E18: Industry-standard F&B margin benchmark
B19: ADVERTISEMENT
B20: Ad spots / month | C20: 40 @ ₹10,000 | D20: Local/regional on-screen + lobby ad inventory for a 3-screen site. | E20: Assumption, sized so ad income sits near PVR INOX's ~6-8% of total revenue
B21: Agency commission | C21: 30% | D21: Standard media-buying agency commission on ad sales. | E21: Industry-standard assumption
B22: OPERATING EXPENSES (MONTHLY)
B23: Property rent | C23: ₹5,00,000 | D23: Implies ~₹65-70/sq.ft on a ~7,500 sq.ft footprint - well below Ahmedabad CG Road high-street rates, consistent with mall-anchor cinema deals. | E23: thesimplebizman.com, Aug 2025 (Ahmedabad CG Road: ₹120-300/sq.ft)
B24: CAM charges | C24: ₹80,000 | D24: Typical mall common-area-maintenance charge of ₹10-15/sq.ft/month. | E24: Standard Indian mall-lease convention
B25: Electricity | C25: ₹1,80,000 | D25: 3-screen HVAC + laser projection load at Gujarat commercial tariffs (~₹7-8/unit). | E25: Assumption based on Gujarat commercial power tariffs
B26: Marketing & promotion | C26: 2% of Ticket+F&B | D26: Typical retail/entertainment marketing budget ratio - formula-linked so it scales with revenue. | E26: Assumption
B27: INVESTMENT (ONE-TIME)
B28: Seat prices | C28: ₹85k-1.5L / seat | D28: Per ConnPlex's own published price specification. | E28: Original franchise price list (franchisor-supplied)
B29: Franchise fee | C29: ₹5,00,000 / screen | D29: Per ConnPlex franchise disclosure. | E29: Original franchise document
B30: Foyer fit-out | C30: ₹3,000/sq.ft × 2,200 sq.ft | D30: Premium cinema-lobby fit-outs in India typically run ₹3,000-6,000/sq.ft. | E30: Industry fit-out cost benchmark (assumption)
B31: Total investment (check) | C31: ~₹3.5-4.0 cr | D31: Lands inside ConnPlex's own disclosed ₹2-4 crore range for the Signature/Luxuriance formats. | E31: franchiseavs.com/connplex-smart-theatres-franchise-in-india/
B32: MARKET CONTEXT
B33: Ahmedabad screen count | C33: 130 theatres (Oct 2025), +10% vs 2023 | D33: Confirms an actively growing exhibition market. | E33: rentechdigital.com
B34: PVR INOX Ahmedabad presence | C34: 36 screens / 6 properties (incl. 9-screen IMAX/LUXE flagship) | D34: Validates premium-format demand in the city. | E34: newsonprojects.com
B35: ConnPlex Gujarat footprint | C35: 33+ screens live, 250 more planned | D35: Brand's own stated Gujarat growth trajectory. | E35: bilkulonline.com, Dec 2024
B36: Gujarati box-office growth | C36: ₹46cr (2015) → ₹104+cr (Oct 2025) | D36: 100%+ decade growth in the regional content pipeline. | E36: articles.uvnetware.com, Jan 2026
B37: India screen density | C37: 1 screen per ~147,000 people vs. USA 1:8,000 | D37: Structural under-screened market cited by the franchisor. | E37: franchiseavs.com/connplex-smart-theatres-franchise-in-india/
B39: Every editable assumption cell also carries an in-cell comment (hover to view) repeating this rationale and source at the point of use.
